Workbook

Sheet Leia-me
B2: 3ª Edição dos Bronzes — Painel do Torneio
B3: Guia rápido de uso desta planilha
B5: ● Sorteio de Capitães
B6: Os 6 Midlaners desta edição — o Mid é o "cabeça do time", então todo Mid vira capitão automaticamente. O sorteio decide qual time cada um vai capitanear. Aperte F9 pra sortear de novo; quando decidirem o resultado, copiem os nomes como valores para a aba Draft e marquem o time de cada Mid na Base Jogadores.
B8: ● Base Jogadores
B9: Lista tratada dos 30 inscritos, com valor em pontos calculado automaticamente a partir do elo (aba 'Valores por Elo'). A coluna 'Time' (destacada em amarelo) é onde os capitães vão marcando o time de cada jogador durante o draft — basta clicar na célula e escolher na lista.
B11: ● Valores por Elo
B12: Tabela de pontos por elo (células em amarelo = editável). Se vocês quiserem recalibrar os valores antes do torneio, alterem aqui — tudo no resto da planilha se atualiza sozinho.
B14: ● Draft
B15: Painel ao vivo do draft: nome/capitão de cada time, orçamento, pontos já gastos, saldo restante, cobertura das 5 rotas por time (com aviso visual se faltar ou sobrar alguma rota) e o elenco de cada time atualizado automaticamente conforme a coluna 'Time' é preenchida na aba Base Jogadores.
B17: ● Dashboard
B18: Gráficos gerais: distribuição de jogadores por elo, distribuição por rota primária e um mapa de calor Elo x Rota.
... B23: Células amarelas = você deve preencher/editar. Células brancas com fórmula = não mexer, atualizam sozinhas.

Sheet Dashboard
B2: Dashboard — 3ª Edição dos Bronzes
B3: Visão geral dos 30 inscritos: elo e rota primária. Atualiza automaticamente se a lista de jogadores mudar.
B6: Elo | C6: Jogadores
B7: Ferro | C7: =COUNTIF('Base Jogadores'!$C$2:$C$31,$B7) -> 0
B8: Bronze | C8: =COUNTIF('Base Jogadores'!$C$2:$C$31,$B8) -> 3
B9: Prata | C9: =COUNTIF('Base Jogadores'!$C$2:$C$31,$B9) -> 2
B10: Ouro | C10: =COUNTIF('Base Jogadores'!$C$2:$C$31,$B10) -> 5
B11: Platina | C11: =COUNTIF('Base Jogadores'!$C$2:$C$31,$B11) -> 8
B12: Esmeralda | C12: =COUNTIF('Base Jogadores'!$C$2:$C$31,$B12) -> 7
B13: Diamante | C13: =COUNTIF('Base Jogadores'!$C$2:$C$31,$B13) -> 4
B14: Mestre | C14: =COUNTIF('Base Jogadores'!$C$2:$C$31,$B14) -> 1
B15: Grão-Mestre | C15: =COUNTIF('Base Jogadores'!$C$2:$C$31,$B15) -> 0
B16: Desafiante | C16: =COUNTIF('Base Jogadores'!$C$2:$C$31,$B16) -> 0
B19: Rota | C19: Primária | D19: Aptos (qualquer rota)
B20: Topo | C20: =COUNTIF('Base Jogadores'!$E$2:$E$31,"Toplane") -> 5 | D20: =SUM('Base Jogadores'!$G$2:$G$31) -> 6
B21: Selva | C21: =COUNTIF('Base Jogadores'!$E$2:$E$31,"Jungler") -> 4 | D21: =SUM('Base Jogadores'!$H$2:$H$31) -> 4
B22: Meio | C22: =COUNTIF('Base Jogadores'!$E$2:$E$31,"Midlane") -> 6 | D22: =SUM('Base Jogadores'!$I$2:$I$31) -> 6
B23: Atirador | C23: =COUNTIF('Base Jogadores'!$E$2:$E$31,"Adcarry") -> 9 | D23: =SUM('Base Jogadores'!$J$2:$J$31) -> 8
B24: Suporte | C24: =COUNTIF('Base Jogadores'!$E$2:$E$31,"Suport") -> 6 | D24: =SUM('Base Jogadores'!$K$2:$K$31) -> 6
B27: Mapa de Calor: Elo x Rota Primária
B28: Elo | C28: Topo | D28: Selva | E28: Meio | F28: Atirador | G28: Suporte
B29: Bronze | C29: =COUNTIFS('Base Jogadores'!$C$2:$C$31,"Bronze",'Base Jogadores'!$E$2:$E$31,"Toplane") -> 0 | D29: =COUNTIFS('Base Jogadores'!$C$2:$C$31,"Bronze",'Base Jogadores'!$E$2:$E$31,"Jungler") -> 1 | E29: =COUNTIFS('Base Jogadores'!$C$2:$C$31,"Bronze",'Base Jogadores'!$E$2:$E$31,"Midlane") -> 0 | F29: =COUNTIFS('Base Jogadores'!$C$2:$C$31,"Bronze",'Base Jogadores'!$E$2:$E$31,"Adcarry") -> 0 | G29: =COUNTIFS('Base Jogadores'!$C$2:$C$31,"Bronze",'Base Jogadores'!$E$2:$E$31,"Suport") -> 2
B30: Prata | C30: =COUNTIFS('Base Jogadores'!$C$2:$C$31,"Prata",'Base Jogadores'!$E$2:$E$31,"Toplane") -> 0 | D30: =COUNTIFS('Base Jogadores'!$C$2:$C$31,"Prata",'Base Jogadores'!$E$2:$E$31,"Jungler") -> 0 | E30: =COUNTIFS('Base Jogadores'!$C$2:$C$31,"Prata",'Base Jogadores'!$E$2:$E$31,"Midlane") -> 1 | F30: =COUNTIFS('Base Jogadores'!$C$2:$C$31,"Prata",'Base Jogadores'!$E$2:$E$31,"Adcarry") -> 1 | G30: =COUNTIFS('Base Jogadores'!$C$2:$C$31,"Prata",'Base Jogadores'!$E$2:$E$31,"Suport") -> 0
B31: Ouro | C31: =COUNTIFS('Base Jogadores'!$C$2:$C$31,"Ouro",'Base Jogadores'!$E$2:$E$31,"Toplane") -> 0 | D31: =COUNTIFS('Base Jogadores'!$C$2:$C$31,"Ouro",'Base Jogadores'!$E$2:$E$31,"Jungler") -> 0 | E31: =COUNTIFS('Base Jogadores'!$C$2:$C$31,"Ouro",'Base Jogadores'!$E$2:$E$31,"Midlane") -> 2 | F31: =COUNTIFS('Base Jogadores'!$C$2:$C$31,"Ouro",'Base Jogadores'!$E$2:$E$31,"Adcarry") -> 2 | G31: =COUNTIFS('Base Jogadores'!$C$2:$C$31,"Ouro",'Base Jogadores'!$E$2:$E$31,"Suport") -> 1
B32: Platina | C32: =COUNTIFS('Base Jogadores'!$C$2:$C$31,"Platina",'Base Jogadores'!$E$2:$E$31,"Toplane") -> 2 | D32: =COUNTIFS('Base Jogadores'!$C$2:$C$31,"Platina",'Base Jogadores'!$E$2:$E$31,"Jungler") -> 0 | E32: =COUNTIFS('Base Jogadores'!$C$2:$C$31,"Platina",'Base Jogadores'!$E$2:$E$31,"Midlane") -> 2 | F32: =COUNTIFS('Base Jogadores'!$C$2:$C$31,"Platina",'Base Jogadores'!$E$2:$E$31,"Adcarry") -> 3 | G32: =COUNTIFS('Base Jogadores'!$C$2:$C$31,"Platina",'Base Jogadores'!$E$2:$E$31,"Suport") -> 1
B33: Esmeralda | C33: =COUNTIFS('Base Jogadores'!$C$2:$C$31,"Esmeralda",'Base Jogadores'!$E$2:$E$31,"Toplane") -> 2 | D33: =COUNTIFS('Base Jogadores'!$C$2:$C$31,"Esmeralda",'Base Jogadores'!$E$2:$E$31,"Jungler") -> 1 | E33: =COUNTIFS('Base Jogadores'!$C$2:$C$31,"Esmeralda",'Base Jogadores'!$E$2:$E$31,"Midlane") -> 0 | F33: =COUNTIFS('Base Jogadores'!$C$2:$C$31,"Esmeralda",'Base Jogadores'!$E$2:$E$31,"Adcarry") -> 2 | G33: =COUNTIFS('Base Jogadores'!$C$2:$C$31,"Esmeralda",'Base Jogadores'!$E$2:$E$31,"Suport") -> 2
B34: Diamante | C34: =COUNTIFS('Base Jogadores'!$C$2:$C$31,"Diamante",'Base Jogadores'!$E$2:$E$31,"Toplane") -> 1 | D34: =COUNTIFS('Base Jogadores'!$C$2:$C$31,"Diamante",'Base Jogadores'!$E$2:$E$31,"Jungler") -> 1 | E34: =COUNTIFS('Base Jogadores'!$C$2:$C$31,"Diamante",'Base Jogadores'!$E$2:$E$31,"Midlane") -> 1 | F34: =COUNTIFS('Base Jogadores'!$C$2:$C$31,"Diamante",'Base Jogadores'!$E$2:$E$31,"Adcarry") -> 1 | G34: =COUNTIFS('Base Jogadores'!$C$2:$C$31,"Diamante",'Base Jogadores'!$E$2:$E$31,"Suport") -> 0
B35: Mestre | C35: =COUNTIFS('Base Jogadores'!$C$2:$C$31,"Mestre",'Base Jogadores'!$E$2:$E$31,"Toplane") -> 0 | D35: =COUNTIFS('Base Jogadores'!$C$2:$C$31,"Mestre",'Base Jogadores'!$E$2:$E$31,"Jungler") -> 1 | E35: =COUNTIFS('Base Jogadores'!$C$2:$C$31,"Mestre",'Base Jogadores'!$E$2:$E$31,"Midlane") -> 0 | F35: =COUNTIFS('Base Jogadores'!$C$2:$C$31,"Mestre",'Base Jogadores'!$E$2:$E$31,"Adcarry") -> 0 | G35: =COUNTIFS('Base Jogadores'!$C$2:$C$31,"Mestre",'Base Jogadores'!$E$2:$E$31,"Suport") -> 0

Sheet Sorteio de Capitães
B2: Sorteio de Capitães — 3ª Edição
B3: Elegíveis: os 6 jogadores de Midlane desta edição — cada Mid é automaticamente o capitão do seu time (a rota "cabeça do time").
B4: Como são exatamente 6 Mids para 6 times, todos os 6 viram capitão — o sorteio aqui decide é QUAL time cada um vai capitanear. Pressione F9 (ou Ctrl+Alt+F9) para sortear de novo. Quando decidirem o resultado final: (1) copiem os 6 nomes como VALORES para a aba Draft (coluna Capitão); e (2) na aba Base Jogadores, preencham a coluna 'Time' de cada um desses 6 Mids com o time que ele vai capitanear — afinal, o capitão também é jogador e ocupa a vaga de Mid do próprio time (o valor dele em pontos entra no orçamento normalmente).
B6: # | C6: Nome | D6: Nickname | E6: Elo | F6: Valor | G6: Número Sorteio | H6: Ordem
B7: 1 | C7: {=IFERROR(INDEX('Base Jogadores'!$A$2:$A$31,MATCH(1,'Base Jogadores'!$Q$2:$Q$31,0)),"")} -> Felipe / Satoshi | D7: {=IFERROR(INDEX('Base Jogadores'!$B$2:$B$31,MATCH(1,'Base Jogadores'!$Q$2:$Q$31,0)),"")} -> Satoshi #VDD | E7: {=IFERROR(INDEX('Base Jogadores'!$C$2:$C$31,MATCH(1,'Base Jogadores'!$Q$2:$Q$31,0)),"")} -> Platina | F7: {=IFERROR(INDEX('Base Jogadores'!$D$2:$D$31,MATCH(1,'Base Jogadores'!$Q$2:$Q$31,0)),"")} -> 5 | G7: =RAND() -> 0.82398081 | H7: =RANK($G7,$G$7:$G$12) -> 3
B8: 2 | C8: {=IFERROR(INDEX('Base Jogadores'!$A$2:$A$31,MATCH(2,'Base Jogadores'!$Q$2:$Q$31,0)),"")} -> Lucas Oliveira | D8: {=IFERROR(INDEX('Base Jogadores'!$B$2:$B$31,MATCH(2,'Base Jogadores'!$Q$2:$Q$31,0)),"")} -> яαzεгαł ッ #yse | E8: {=IFERROR(INDEX('Base Jogadores'!$C$2:$C$31,MATCH(2,'Base Jogadores'!$Q$2:$Q$31,0)),"")} -> Diamante | F8: {=IFERROR(INDEX('Base Jogadores'!$D$2:$D$31,MATCH(2,'Base Jogadores'!$Q$2:$Q$31,0)),"")} -> 8 | G8: =RAND() -> 0.9628603 | H8: =RANK($G8,$G$7:$G$12) -> 1
B9: 3 | C9: {=IFERROR(INDEX('Base Jogadores'!$A$2:$A$31,MATCH(3,'Base Jogadores'!$Q$2:$Q$31,0)),"")} -> Junior | D9: {=IFERROR(INDEX('Base Jogadores'!$B$2:$B$31,MATCH(3,'Base Jogadores'!$Q$2:$Q$31,0)),"")} -> Sabor Energético #1777 | E9: {=IFERROR(INDEX('Base Jogadores'!$C$2:$C$31,MATCH(3,'Base Jogadores'!$Q$2:$Q$31,0)),"")} -> Prata | F9: {=IFERROR(INDEX('Base Jogadores'!$D$2:$D$31,MATCH(3,'Base Jogadores'!$Q$2:$Q$31,0)),"")} -> 3 | G9: =RAND() -> 0.91135502 | H9: =RANK($G9,$G$7:$G$12) -> 2
B10: 4 | C10: {=IFERROR(INDEX('Base Jogadores'!$A$2:$A$31,MATCH(4,'Base Jogadores'!$Q$2:$Q$31,0)),"")} -> Jeferson/ Heimer | D10: {=IFERROR(INDEX('Base Jogadores'!$B$2:$B$31,MATCH(4,'Base Jogadores'!$Q$2:$Q$31,0)),"")} -> N4firida agiota #7937 | E10: {=IFERROR(INDEX('Base Jogadores'!$C$2:$C$31,MATCH(4,'Base Jogadores'!$Q$2:$Q$31,0)),"")} -> Ouro | F10: {=IFERROR(INDEX('Base Jogadores'!$D$2:$D$31,MATCH(4,'Base Jogadores'!$Q$2:$Q$31,0)),"")} -> 4 | G10: =RAND() -> 0.40445846 | H10: =RANK($G10,$G$7:$G$12) -> 5
B11: 5 | C11: {=IFERROR(INDEX('Base Jogadores'!$A$2:$A$31,MATCH(5,'Base Jogadores'!$Q$2:$Q$31,0)),"")} -> Heitor Silva | D11: {=IFERROR(INDEX('Base Jogadores'!$B$2:$B$31,MATCH(5,'Base Jogadores'!$Q$2:$Q$31,0)),"")} -> tikin d calcinha#jcdk | E11: {=IFERROR(INDEX('Base Jogadores'!$C$2:$C$31,MATCH(5,'Base Jogadores'!$Q$2:$Q$31,0)),"")} -> Ouro | F11: {=IFERROR(INDEX('Base Jogadores'!$D$2:$D$31,MATCH(5,'Base Jogadores'!$Q$2:$Q$31,0)),"")} -> 4 | G11: =RAND() -> 0.10340045 | H11: =RANK($G11,$G$7:$G$12) -> 6
B12: 6 | C12: {=IFERROR(INDEX('Base Jogadores'!$A$2:$A$31,MATCH(6,'Base Jogadores'!$Q$2:$Q$31,0)),"")} -> Luix Silva | D12: {=IFERROR(INDEX('Base Jogadores'!$B$2:$B$31,MATCH(6,'Base Jogadores'!$Q$2:$Q$31,0)),"")} -> Z0E Baiana #br1 | E12: {=IFERROR(INDEX('Base Jogadores'!$C$2:$C$31,MATCH(6,'Base Jogadores'!$Q$2:$Q$31,0)),"")} -> Platina | F12: {=IFERROR(INDEX('Base Jogadores'!$D$2:$D$31,MATCH(6,'Base Jogadores'!$Q$2:$Q$31,0)),"")} -> 5 | G12: =RAND() -> 0.7416503 | H12: =RANK($G12,$G$7:$G$12) -> 4
B15: Capitães Sorteados
B16: Time | C16: Nome | D16: Nickname | E16: Elo | F16: Valor
B17: Time 1 | C17: {=IFERROR(INDEX($C$7:$C$12,MATCH(1,$H$7:$H$12,0)),"")} -> Lucas Oliveira | D17: {=IFERROR(INDEX($D$7:$D$12,MATCH(1,$H$7:$H$12,0)),"")} -> яαzεгαł ッ #yse | E17: {=IFERROR(INDEX($E$7:$E$12,MATCH(1,$H$7:$H$12,0)),"")} -> Diamante | F17: {=IFERROR(INDEX($F$7:$F$12,MATCH(1,$H$7:$H$12,0)),"")} -> 8
B18: Time 2 | C18: {=IFERROR(INDEX($C$7:$C$12,MATCH(2,$H$7:$H$12,0)),"")} -> Junior | D18: {=IFERROR(INDEX($D$7:$D$12,MATCH(2,$H$7:$H$12,0)),"")} -> Sabor Energético #1777 | E18: {=IFERROR(INDEX($E$7:$E$12,MATCH(2,$H$7:$H$12,0)),"")} -> Prata | F18: {=IFERROR(INDEX($F$7:$F$12,MATCH(2,$H$7:$H$12,0)),"")} -> 3
B19: Time 3 | C19: {=IFERROR(INDEX($C$7:$C$12,MATCH(3,$H$7:$H$12,0)),"")} -> Felipe / Satoshi | D19: {=IFERROR(INDEX($D$7:$D$12,MATCH(3,$H$7:$H$12,0)),"")} -> Satoshi #VDD | E19: {=IFERROR(INDEX($E$7:$E$12,MATCH(3,$H$7:$H$12,0)),"")} -> Platina | F19: {=IFERROR(INDEX($F$7:$F$12,MATCH(3,$H$7:$H$12,0)),"")} -> 5
B20: Time 4 | C20: {=IFERROR(INDEX($C$7:$C$12,MATCH(4,$H$7:$H$12,0)),"")} -> Luix Silva | D20: {=IFERROR(INDEX($D$7:$D$12,MATCH(4,$H$7:$H$12,0)),"")} -> Z0E Baiana #br1 | E20: {=IFERROR(INDEX($E$7:$E$12,MATCH(4,$H$7:$H$12,0)),"")} -> Platina | F20: {=IFERROR(INDEX($F$7:$F$12,MATCH(4,$H$7:$H$12,0)),"")} -> 5
B21: Time 5 | C21: {=IFERROR(INDEX($C$7:$C$12,MATCH(5,$H$7:$H$12,0)),"")} -> Jeferson/ Heimer | D21: {=IFERROR(INDEX($D$7:$D$12,MATCH(5,$H$7:$H$12,0)),"")} -> N4firida agiota #7937 | E21: {=IFERROR(INDEX($E$7:$E$12,MATCH(5,$H$7:$H$12,0)),"")} -> Ouro | F21: {=IFERROR(INDEX($F$7:$F$12,MATCH(5,$H$7:$H$12,0)),"")} -> 4
B22: Time 6 | C22: {=IFERROR(INDEX($C$7:$C$12,MATCH(6,$H$7:$H$12,0)),"")} -> Heitor Silva | D22: {=IFERROR(INDEX($D$7:$D$12,MATCH(6,$H$7:$H$12,0)),"")} -> tikin d calcinha#jcdk | E22: {=IFERROR(INDEX($E$7:$E$12,MATCH(6,$H$7:$H$12,0)),"")} -> Ouro | F22: {=IFERROR(INDEX($F$7:$F$12,MATCH(6,$H$7:$H$12,0)),"")} -> 4
B24: O "Time 1" a "Time 6" aqui é só a ordem do sorteio — vocês podem renomear os times como quiserem depois na aba Draft.

Sheet Draft
B2: Draft dos Times — 3ª Edição dos Bronzes
B3: Preencha o nome do time e o capitão. O orçamento já vem sugerido — edite se quiser. Tudo abaixo atualiza sozinho conforme a coluna 'Time' é preenchida na aba Base Jogadores.
B5: Time | C5: Capitão | D5: Orçamento (pts) | E5: Pontos Gastos | F5: Saldo | G5: Jogadores | H5: Status
B6: Time 1 | D6: ='Valores por Elo'!$C$23 -> 30 | E6: =SUMIFS('Base Jogadores'!$D$2:$D$31,'Base Jogadores'!$M$2:$M$31,$B6) -> 26 | F6: =D6-E6 -> 4 | G6: =COUNTIF('Base Jogadores'!$M$2:$M$31,$B6) -> 5 | H6: =IF(G6>5,"⚠ Excesso",IF(F6<0,"⚠ Orçamento estourado",IF(G6=5,"✅ Completo","Incompleto"))) -> ✅ Completo
B7: Time 2 | D7: ='Valores por Elo'!$C$23 -> 30 | E7: =SUMIFS('Base Jogadores'!$D$2:$D$31,'Base Jogadores'!$M$2:$M$31,$B7) -> 29 | F7: =D7-E7 -> 1 | G7: =COUNTIF('Base Jogadores'!$M$2:$M$31,$B7) -> 5 | H7: =IF(G7>5,"⚠ Excesso",IF(F7<0,"⚠ Orçamento estourado",IF(G7=5,"✅ Completo","Incompleto"))) -> ✅ Completo
B8: Time 3 | D8: ='Valores por Elo'!$C$23 -> 30 | E8: =SUMIFS('Base Jogadores'!$D$2:$D$31,'Base Jogadores'!$M$2:$M$31,$B8) -> 25 | F8: =D8-E8 -> 5 | G8: =COUNTIF('Base Jogadores'!$M$2:$M$31,$B8) -> 5 | H8: =IF(G8>5,"⚠ Excesso",IF(F8<0,"⚠ Orçamento estourado",IF(G8=5,"✅ Completo","Incompleto"))) -> ✅ Completo
B9: Time 4 | D9: ='Valores por Elo'!$C$23 -> 30 | E9: =SUMIFS('Base Jogadores'!$D$2:$D$31,'Base Jogadores'!$M$2:$M$31,$B9) -> 21 | F9: =D9-E9 -> 9 | G9: =COUNTIF('Base Jogadores'!$M$2:$M$31,$B9) -> 5 | H9: =IF(G9>5,"⚠ Excesso",IF(F9<0,"⚠ Orçamento estourado",IF(G9=5,"✅ Completo","Incompleto"))) -> ✅ Completo
B10: Time 5 | D10: ='Valores por Elo'!$C$23 -> 30 | E10: =SUMIFS('Base Jogadores'!$D$2:$D$31,'Base Jogadores'!$M$2:$M$31,$B10) -> 26 | F10: =D10-E10 -> 4 | G10: =COUNTIF('Base Jogadores'!$M$2:$M$31,$B10) -> 5 | H10: =IF(G10>5,"⚠ Excesso",IF(F10<0,"⚠ Orçamento estourado",IF(G10=5,"✅ Completo","Incompleto"))) -> ✅ Completo
B11: Time 6 | D11: ='Valores por Elo'!$C$23 -> 30 | E11: =SUMIFS('Base Jogadores'!$D$2:$D$31,'Base Jogadores'!$M$2:$M$31,$B11) -> 29 | F11: =D11-E11 -> 1 | G11: =COUNTIF('Base Jogadores'!$M$2:$M$31,$B11) -> 5 | H11: =IF(G11>5,"⚠ Excesso",IF(F11<0,"⚠ Orçamento estourado",IF(G11=5,"✅ Completo","Incompleto"))) -> ✅ Completo
B14: Cobertura de Rotas por Time
B15: Rota | C15: =$B$6 -> Time 1 | D15: =$B$7 -> Time 2 | E15: =$B$8 -> Time 3 | F15: =$B$9 -> Time 4 | G15: =$B$10 -> Time 5 | H15: =$B$11 -> Time 6
B16: Topo | C16: =COUNTIFS('Base Jogadores'!$E$2:$E$31,"Toplane",'Base Jogadores'!$M$2:$M$31,C$15) -> 1 | D16: =COUNTIFS('Base Jogadores'!$E$2:$E$31,"Toplane",'Base Jogadores'!$M$2:$M$31,D$15) -> 1 | E16: =COUNTIFS('Base Jogadores'!$E$2:$E$31,"Toplane",'Base Jogadores'!$M$2:$M$31,E$15) -> 0 | F16: =COUNTIFS('Base Jogadores'!$E$2:$E$31,"Toplane",'Base Jogadores'!$M$2:$M$31,F$15) -> 1 | G16: =COUNTIFS('Base Jogadores'!$E$2:$E$31,"Toplane",'Base Jogadores'!$M$2:$M$31,G$15) -> 1 | H16: =COUNTIFS('Base Jogadores'!$E$2:$E$31,"Toplane",'Base Jogadores'!$M$2:$M$31,H$15) -> 1
B17: Selva | C17: =COUNTIFS('Base Jogadores'!$E$2:$E$31,"Jungler",'Base Jogadores'!$M$2:$M$31,C$15) -> 1 | D17: =COUNTIFS('Base Jogadores'!$E$2:$E$31,"Jungler",'Base Jogadores'!$M$2:$M$31,D$15) -> 1 | E17: =COUNTIFS('Base Jogadores'!$E$2:$E$31,"Jungler",'Base Jogadores'!$M$2:$M$31,E$15) -> 1 | F17: =COUNTIFS('Base Jogadores'!$E$2:$E$31,"Jungler",'Base Jogadores'!$M$2:$M$31,F$15) -> 1 | G17: =COUNTIFS('Base Jogadores'!$E$2:$E$31,"Jungler",'Base Jogadores'!$M$2:$M$31,G$15) -> 0 | H17: =COUNTIFS('Base Jogadores'!$E$2:$E$31,"Jungler",'Base Jogadores'!$M$2:$M$31,H$15) -> 0
B18: Meio | C18: =COUNTIFS('Base Jogadores'!$E$2:$E$31,"Midlane",'Base Jogadores'!$M$2:$M$31,C$15) -> 1 | D18: =COUNTIFS('Base Jogadores'!$E$2:$E$31,"Midlane",'Base Jogadores'!$M$2:$M$31,D$15) -> 1 | E18: =COUNTIFS('Base Jogadores'!$E$2:$E$31,"Midlane",'Base Jogadores'!$M$2:$M$31,E$15) -> 1 | F18: =COUNTIFS('Base Jogadores'!$E$2:$E$31,"Midlane",'Base Jogadores'!$M$2:$M$31,F$15) -> 1 | G18: =COUNTIFS('Base Jogadores'!$E$2:$E$31,"Midlane",'Base Jogadores'!$M$2:$M$31,G$15) -> 1 | H18: =COUNTIFS('Base Jogadores'!$E$2:$E$31,"Midlane",'Base Jogadores'!$M$2:$M$31,H$15) -> 1
B19: Atirador | C19: =COUNTIFS('Base Jogadores'!$E$2:$E$31,"Adcarry",'Base Jogadores'!$M$2:$M$31,C$15) -> 1 | D19: =COUNTIFS('Base Jogadores'!$E$2:$E$31,"Adcarry",'Base Jogadores'!$M$2:$M$31,D$15) -> 1 | E19: =COUNTIFS('Base Jogadores'!$E$2:$E$31,"Adcarry",'Base Jogadores'!$M$2:$M$31,E$15) -> 3 | F19: =COUNTIFS('Base Jogadores'!$E$2:$E$31,"Adcarry",'Base Jogadores'!$M$2:$M$31,F$15) -> 1 | G19: =COUNTIFS('Base Jogadores'!$E$2:$E$31,"Adcarry",'Base Jogadores'!$M$2:$M$31,G$15) -> 1 | H19: =COUNTIFS('Base Jogadores'!$E$2:$E$31,"Adcarry",'Base Jogadores'!$M$2:$M$31,H$15) -> 2
B20: Suporte | C20: =COUNTIFS('Base Jogadores'!$E$2:$E$31,"Suport",'Base Jogadores'!$M$2:$M$31,C$15) -> 1 | D20: =COUNTIFS('Base Jogadores'!$E$2:$E$31,"Suport",'Base Jogadores'!$M$2:$M$31,D$15) -> 1 | E20: =COUNTIFS('Base Jogadores'!$E$2:$E$31,"Suport",'Base Jogadores'!$M$2:$M$31,E$15) -> 0 | F20: =COUNTIFS('Base Jogadores'!$E$2:$E$31,"Suport",'Base Jogadores'!$M$2:$M$31,F$15) -> 1 | G20: =COUNTIFS('Base Jogadores'!$E$2:$E$31,"Suport",'Base Jogadores'!$M$2:$M$31,G$15) -> 2 | H20: =COUNTIFS('Base Jogadores'!$E$2:$E$31,"Suport",'Base Jogadores'!$M$2:$M$31,H$15) -> 1
B22: Verde = rota coberta (1 titular) · Amarelo = rota ainda sem jogador · Vermelho = rota duplicada (mais de 1 jogador na mesma posição).
B25: Elenco de Cada Time
B27: =$B$6&" — Capitão: "&IF($C$6="","(HEITOR SILVA)",$C$6) -> Time 1 — Capitão: (HEITOR SILVA)
B28: # | C28: Nome | D28: Nickname | E28: Elo | F28: Valor | G28: Rota
B29: 1 | C29: {=IFERROR(INDEX('Base Jogadores'!$A$2:$A$31,MATCH($B$6&"|"&1,'Base Jogadores'!$O$2:$O$31,0)),"")} -> Alefh Nakayama | D29: {=IFERROR(INDEX('Base Jogadores'!$B$2:$B$31,MATCH($B$6&"|"&1,'Base Jogadores'!$O$2:$O$31,0)),"")} -> nak4y#JPN | E29: {=IFERROR(INDEX('Base Jogadores'!$C$2:$C$31,MATCH($B$6&"|"&1,'Base Jogadores'!$O$2:$O$31,0)),"")} -> Mestre | F29: {=IFERROR(INDEX('Base Jogadores'!$D$2:$D$31,MATCH($B$6&"|"&1,'Base Jogadores'!$O$2:$O$31,0)),"")} -> 10 | G29: {=IFERROR(INDEX('Base Jogadores'!$E$2:$E$31,MATCH($B$6&"|"&1,'Base Jogadores'!$O$2:$O$31,0)),"")} -> Jungler
B30: 2 | C30: {=IFERROR(INDEX('Base Jogadores'!$A$2:$A$31,MATCH($B$6&"|"&2,'Base Jogadores'!$O$2:$O$31,0)),"")} -> Heitor Silva | D30: {=IFERROR(INDEX('Base Jogadores'!$B$2:$B$31,MATCH($B$6&"|"&2,'Base Jogadores'!$O$2:$O$31,0)),"")} -> tikin d calcinha#jcdk | E30: {=IFERROR(INDEX('Base Jogadores'!$C$2:$C$31,MATCH($B$6&"|"&2,'Base Jogadores'!$O$2:$O$31,0)),"")} -> Ouro | F30: {=IFERROR(INDEX('Base Jogadores'!$D$2:$D$31,MATCH($B$6&"|"&2,'Base Jogadores'!$O$2:$O$31,0)),"")} -> 4 | G30: {=IFERROR(INDEX('Base Jogadores'!$E$2:$E$31,MATCH($B$6&"|"&2,'Base Jogadores'!$O$2:$O$31,0)),"")} -> Midlane
B31: 3 | C31: {=IFERROR(INDEX('Base Jogadores'!$A$2:$A$31,MATCH($B$6&"|"&3,'Base Jogadores'!$O$2:$O$31,0)),"")} -> Álvaro Jorge | D31: {=IFERROR(INDEX('Base Jogadores'!$B$2:$B$31,MATCH($B$6&"|"&3,'Base Jogadores'!$O$2:$O$31,0)),"")} -> Tapa de doido #ats | E31: {=IFERROR(INDEX('Base Jogadores'!$C$2:$C$31,MATCH($B$6&"|"&3,'Base Jogadores'!$O$2:$O$31,0)),"")} -> Platina | F31: {=IFERROR(INDEX('Base Jogadores'!$D$2:$D$31,MATCH($B$6&"|"&3,'Base Jogadores'!$O$2:$O$31,0)),"")} -> 5 | G31: {=IFERROR(INDEX('Base Jogadores'!$E$2:$E$31,MATCH($B$6&"|"&3,'Base Jogadores'!$O$2:$O$31,0)),"")} -> Toplane
B32: 4 | C32: {=IFERROR(INDEX('Base Jogadores'!$A$2:$A$31,MATCH($B$6&"|"&4,'Base Jogadores'!$O$2:$O$31,0)),"")} -> Lipão Campolina | D32: {=IFERROR(INDEX('Base Jogadores'!$B$2:$B$31,MATCH($B$6&"|"&4,'Base Jogadores'!$O$2:$O$31,0)),"")} -> GAR3NA#333 | E32: {=IFERROR(INDEX('Base Jogadores'!$C$2:$C$31,MATCH($B$6&"|"&4,'Base Jogadores'!$O$2:$O$31,0)),"")} -> Ouro | F32: {=IFERROR(INDEX('Base Jogadores'!$D$2:$D$31,MATCH($B$6&"|"&4,'Base Jogadores'!$O$2:$O$31,0)),"")} -> 4 | G32: {=IFERROR(INDEX('Base Jogadores'!$E$2:$E$31,MATCH($B$6&"|"&4,'Base Jogadores'!$O$2:$O$31,0)),"")} -> Suport
B33: 5 | C33: {=IFERROR(INDEX('Base Jogadores'!$A$2:$A$31,MATCH($B$6&"|"&5,'Base Jogadores'!$O$2:$O$31,0)),"")} -> Fernando da Silva | D33: {=IFERROR(INDEX('Base Jogadores'!$B$2:$B$31,MATCH($B$6&"|"&5,'Base Jogadores'!$O$2:$O$31,0)),"")} -> Iranildo Gari#Pilar | E33: {=IFERROR(INDEX('Base Jogadores'!$C$2:$C$31,MATCH($B$6&"|"&5,'Base Jogadores'!$O$2:$O$31,0)),"")} -> Prata | F33: {=IFERROR(INDEX('Base Jogadores'!$D$2:$D$31,MATCH($B$6&"|"&5,'Base Jogadores'!$O$2:$O$31,0)),"")} -> 3 | G33: {=IFERROR(INDEX('Base Jogadores'!$E$2:$E$31,MATCH($B$6&"|"&5,'Base Jogadores'!$O$2:$O$31,0)),"")} -> Adcarry
B35: =$B$7&" — Capitão: "&IF($C$7="","(SATOSHI)",$C$7) -> Time 2 — Capitão: (SATOSHI)
B36: # | C36: Nome | D36: Nickname | E36: Elo | F36: Valor | G36: Rota
B37: 1 | C37: {=IFERROR(INDEX('Base Jogadores'!$A$2:$A$31,MATCH($B$7&"|"&1,'Base Jogadores'!$O$2:$O$31,0)),"")} -> Luiz Felipe | D37: {=IFERROR(INDEX('Base Jogadores'!$B$2:$B$31,MATCH($B$7&"|"&1,'Base Jogadores'!$O$2:$O$31,0)),"")} -> mxxDragonxxm | E37: {=IFERROR(INDEX('Base Jogadores'!$C$2:$C$31,MATCH($B$7&"|"&1,'Base Jogadores'!$O$2:$O$31,0)),"")} -> Diamante | F37: {=IFERROR(INDEX('Base Jogadores'!$D$2:$D$31,MATCH($B$7&"|"&1,'Base Jogadores'!$O$2:$O$31,0)),"")} -> 8 | G37: {=IFERROR(INDEX('Base Jogadores'!$E$2:$E$31,MATCH($B$7&"|"&1,'Base Jogadores'!$O$2:$O$31,0)),"")} -> Jungler
B38: 2 | C38: {=IFERROR(INDEX('Base Jogadores'!$A$2:$A$31,MATCH($B$7&"|"&2,'Base Jogadores'!$O$2:$O$31,0)),"")} -> Felipe / Satoshi | D38: {=IFERROR(INDEX('Base Jogadores'!$B$2:$B$31,MATCH($B$7&"|"&2,'Base Jogadores'!$O$2:$O$31,0)),"")} -> Satoshi #VDD | E38: {=IFERROR(INDEX('Base Jogadores'!$C$2:$C$31,MATCH($B$7&"|"&2,'Base Jogadores'!$O$2:$O$31,0)),"")} -> Platina | F38: {=IFERROR(INDEX('Base Jogadores'!$D$2:$D$31,MATCH($B$7&"|"&2,'Base Jogadores'!$O$2:$O$31,0)),"")} -> 5 | G38: {=IFERROR(INDEX('Base Jogadores'!$E$2:$E$31,MATCH($B$7&"|"&2,'Base Jogadores'!$O$2:$O$31,0)),"")} -> Midlane
B39: 3 | C39: {=IFERROR(INDEX('Base Jogadores'!$A$2:$A$31,MATCH($B$7&"|"&3,'Base Jogadores'!$O$2:$O$31,0)),"")} -> THALISSON VIEIRA | D39: {=IFERROR(INDEX('Base Jogadores'!$B$2:$B$31,MATCH($B$7&"|"&3,'Base Jogadores'!$O$2:$O$31,0)),"")} -> THALAO # FIRST | E39: {=IFERROR(INDEX('Base Jogadores'!$C$2:$C$31,MATCH($B$7&"|"&3,'Base Jogadores'!$O$2:$O$31,0)),"")} -> Bronze | F39: {=IFERROR(INDEX('Base Jogadores'!$D$2:$D$31,MATCH($B$7&"|"&3,'Base Jogadores'!$O$2:$O$31,0)),"")} -> 2 | G39: {=IFERROR(INDEX('Base Jogadores'!$E$2:$E$31,MATCH($B$7&"|"&3,'Base Jogadores'!$O$2:$O$31,0)),"")} -> Suport
B40: 4 | C40: {=IFERROR(INDEX('Base Jogadores'!$A$2:$A$31,MATCH($B$7&"|"&4,'Base Jogadores'!$O$2:$O$31,0)),"")} -> Pedro Lucas PL | D40: {=IFERROR(INDEX('Base Jogadores'!$B$2:$B$31,MATCH($B$7&"|"&4,'Base Jogadores'!$O$2:$O$31,0)),"")} -> Peideicaldinho#pei | E40: {=IFERROR(INDEX('Base Jogadores'!$C$2:$C$31,MATCH($B$7&"|"&4,'Base Jogadores'!$O$2:$O$31,0)),"")} -> Esmeralda | F40: {=IFERROR(INDEX('Base Jogadores'!$D$2:$D$31,MATCH($B$7&"|"&4,'Base Jogadores'!$O$2:$O$31,0)),"")} -> 6 | G40: {=IFERROR(INDEX('Base Jogadores'!$E$2:$E$31,MATCH($B$7&"|"&4,'Base Jogadores'!$O$2:$O$31,0)),"")} -> Toplane
B41: 5 | C41: {=IFERROR(INDEX('Base Jogadores'!$A$2:$A$31,MATCH($B$7&"|"&5,'Base Jogadores'!$O$2:$O$31,0)),"")} -> Nicollas Castro | D41: {=IFERROR(INDEX('Base Jogadores'!$B$2:$B$31,MATCH($B$7&"|"&5,'Base Jogadores'!$O$2:$O$31,0)),"")} -> ctz #444 | E41: {=IFERROR(INDEX('Base Jogadores'!$C$2:$C$31,MATCH($B$7&"|"&5,'Base Jogadores'!$O$2:$O$31,0)),"")} -> Diamante | F41: {=IFERROR(INDEX('Base Jogadores'!$D$2:$D$31,MATCH($B$7&"|"&5,'Base Jogadores'!$O$2:$O$31,0)),"")} -> 8 | G41: {=IFERROR(INDEX('Base Jogadores'!$E$2:$E$31,MATCH($B$7&"|"&5,'Base Jogadores'!$O$2:$O$31,0)),"")} -> Adcarry
B43: =$B$8&" — Capitão: "&IF($C$8="","(HEIMER)",$C$8) -> Time 3 — Capitão: (HEIMER)
B44: # | C44: Nome | D44: Nickname | E44: Elo | F44: Valor | G44: Rota
B45: 1 | C45: {=IFERROR(INDEX('Base Jogadores'!$A$2:$A$31,MATCH($B$8&"|"&1,'Base Jogadores'!$O$2:$O$31,0)),"")} -> Hygor rodrigo | D45: {=IFERROR(INDEX('Base Jogadores'!$B$2:$B$31,MATCH($B$8&"|"&1,'Base Jogadores'!$O$2:$O$31,0)),"")} -> Hikolin#2112 | E45: {=IFERROR(INDEX('Base Jogadores'!$C$2:$C$31,MATCH($B$8&"|"&1,'Base Jogadores'!$O$2:$O$31,0)),"")} -> Esmeralda | F45: {=IFERROR(INDEX('Base Jogadores'!$D$2:$D$31,MATCH($B$8&"|"&1,'Base Jogadores'!$O$2:$O$31,0)),"")} -> 6 | G45: {=IFERROR(INDEX('Base Jogadores'!$E$2:$E$31,MATCH($B$8&"|"&1,'Base Jogadores'!$O$2:$O$31,0)),"")} -> Adcarry
B46: 2 | C46: {=IFERROR(INDEX('Base Jogadores'!$A$2:$A$31,MATCH($B$8&"|"&2,'Base Jogadores'!$O$2:$O$31,0)),"")} -> Jeferson/ Heimer | D46: {=IFERROR(INDEX('Base Jogadores'!$B$2:$B$31,MATCH($B$8&"|"&2,'Base Jogadores'!$O$2:$O$31,0)),"")} -> N4firida agiota #7937 | E46: {=IFERROR(INDEX('Base Jogadores'!$C$2:$C$31,MATCH($B$8&"|"&2,'Base Jogadores'!$O$2:$O$31,0)),"")} -> Ouro | F46: {=IFERROR(INDEX('Base Jogadores'!$D$2:$D$31,MATCH($B$8&"|"&2,'Base Jogadores'!$O$2:$O$31,0)),"")} -> 4 | G46: {=IFERROR(INDEX('Base Jogadores'!$E$2:$E$31,MATCH($B$8&"|"&2,'Base Jogadores'!$O$2:$O$31,0)),"")} -> Midlane
B47: 3 | C47: {=IFERROR(INDEX('Base Jogadores'!$A$2:$A$31,MATCH($B$8&"|"&3,'Base Jogadores'!$O$2:$O$31,0)),"")} -> Artur Rodrigues | D47: {=IFERROR(INDEX('Base Jogadores'!$B$2:$B$31,MATCH($B$8&"|"&3,'Base Jogadores'!$O$2:$O$31,0)),"")} -> Sr Hades#2522 | E47: {=IFERROR(INDEX('Base Jogadores'!$C$2:$C$31,MATCH($B$8&"|"&3,'Base Jogadores'!$O$2:$O$31,0)),"")} -> Ouro | F47: {=IFERROR(INDEX('Base Jogadores'!$D$2:$D$31,MATCH($B$8&"|"&3,'Base Jogadores'!$O$2:$O$31,0)),"")} -> 4 | G47: {=IFERROR(INDEX('Base Jogadores'!$E$2:$E$31,MATCH($B$8&"|"&3,'Base Jogadores'!$O$2:$O$31,0)),"")} -> Adcarry
B48: 4 | C48: {=IFERROR(INDEX('Base Jogadores'!$A$2:$A$31,MATCH($B$8&"|"&4,'Base Jogadores'!$O$2:$O$31,0)),"")} -> Lucas | D48: {=IFERROR(INDEX('Base Jogadores'!$B$2:$B$31,MATCH($B$8&"|"&4,'Base Jogadores'!$O$2:$O$31,0)),"")} -> Onigami | E48: {=IFERROR(INDEX('Base Jogadores'!$C$2:$C$31,MATCH($B$8&"|"&4,'Base Jogadores'!$O$2:$O$31,0)),"")} -> Platina | F48: {=IFERROR(INDEX('Base Jogadores'!$D$2:$D$31,MATCH($B$8&"|"&4,'Base Jogadores'!$O$2:$O$31,0)),"")} -> 5 | G48: {=IFERROR(INDEX('Base Jogadores'!$E$2:$E$31,MATCH($B$8&"|"&4,'Base Jogadores'!$O$2:$O$31,0)),"")} -> Adcarry
B49: 5 | C49: {=IFERROR(INDEX('Base Jogadores'!$A$2:$A$31,MATCH($B$8&"|"&5,'Base Jogadores'!$O$2:$O$31,0)),"")} -> Joao Pedo Barauna Vilela | D49: {=IFERROR(INDEX('Base Jogadores'!$B$2:$B$31,MATCH($B$8&"|"&5,'Base Jogadores'!$O$2:$O$31,0)),"")} -> Famoso Parrudao #6969 | E49: {=IFERROR(INDEX('Base Jogadores'!$C$2:$C$31,MATCH($B$8&"|"&5,'Base Jogadores'!$O$2:$O$31,0)),"")} -> Esmeralda | F49: {=IFERROR(INDEX('Base Jogadores'!$D$2:$D$31,MATCH($B$8&"|"&5,'Base Jogadores'!$O$2:$O$31,0)),"")} -> 6 | G49: {=IFERROR(INDEX('Base Jogadores'!$E$2:$E$31,MATCH($B$8&"|"&5,'Base Jogadores'!$O$2:$O$31,0)),"")} -> Jungler
B51: =$B$9&" — Capitão: "&IF($C$9="","(SABOR ENERGÉTICO)",$C$9) -> Time 4 — Capitão: (SABOR ENERGÉTICO)
...

Sheet Base Jogadores
A1: Nome | B1: Nickname | C1: Elo | D1: Valor (pts) | E1: Rota Primária | F1: Rotas (todas) | G1: Topo | H1: Selva | I1: Meio | J1: Atirador | K1: Suporte | L1: Mono Champion | M1: Time | N1: OrdemNoTime | O1: Chave | P1: Elegivel | Q1: OrdemElegivel
A2: Luiz Felipe | B2: mxxDragonxxm #br1 | C2: Diamante | D2: {=INDEX('Valores por Elo'!$C$6:$C$15,MATCH($C2,'Valores por Elo'!$B$6:$B$15,0))} -> 8 | E2: Jungler | F2: Jungler | G2: =IF(ISNUMBER(SEARCH("Toplane",$F2)),1,0) -> 0 | H2: =IF(ISNUMBER(SEARCH("Jungler",$F2)),1,0) -> 1 | I2: =IF(ISNUMBER(SEARCH("Midlane",$F2)),1,0) -> 0 | J2: =IF(ISNUMBER(SEARCH("Adcarry",$F2)),1,0) -> 0 | K2: =IF(ISNUMBER(SEARCH("Suport",$F2)),1,0) -> 0 | L2: Não | M2: Time 2 | N2: =IF($M2="","",COUNTIF($M$2:$M2,$M2)) -> 1 | O2: =IF($M2="","",$M2&"|"&$N2) -> Time 2|1 | P2: =IF($E2="Midlane",1,0) -> 0 | Q2: =IF($P2=1,COUNTIF($P$2:$P2,1),"")
A3: Hygor rodrigo | B3: Hikolin#2112 | C3: Esmeralda | D3: {=INDEX('Valores por Elo'!$C$6:$C$15,MATCH($C3,'Valores por Elo'!$B$6:$B$15,0))} -> 6 | E3: Adcarry | F3: Adcarry | G3: =IF(ISNUMBER(SEARCH("Toplane",$F3)),1,0) -> 0 | H3: =IF(ISNUMBER(SEARCH("Jungler",$F3)),1,0) -> 0 | I3: =IF(ISNUMBER(SEARCH("Midlane",$F3)),1,0) -> 0 | J3: =IF(ISNUMBER(SEARCH("Adcarry",$F3)),1,0) -> 1 | K3: =IF(ISNUMBER(SEARCH("Suport",$F3)),1,0) -> 0 | L3: Não | M3: Time 3 | N3: =IF($M3="","",COUNTIF($M$2:$M3,$M3)) -> 1 | O3: =IF($M3="","",$M3&"|"&$N3) -> Time 3|1 | P3: =IF($E3="Midlane",1,0) -> 0 | Q3: =IF($P3=1,COUNTIF($P$2:$P3,1),"")
A4: Felipe / Satoshi | B4: Satoshi #VDD | C4: Platina | D4: {=INDEX('Valores por Elo'!$C$6:$C$15,MATCH($C4,'Valores por Elo'!$B$6:$B$15,0))} -> 5 | E4: Midlane | F4: Midlane | G4: =IF(ISNUMBER(SEARCH("Toplane",$F4)),1,0) -> 0 | H4: =IF(ISNUMBER(SEARCH("Jungler",$F4)),1,0) -> 0 | I4: =IF(ISNUMBER(SEARCH("Midlane",$F4)),1,0) -> 1 | J4: =IF(ISNUMBER(SEARCH("Adcarry",$F4)),1,0) -> 0 | K4: =IF(ISNUMBER(SEARCH("Suport",$F4)),1,0) -> 0 | L4: Não | M4: Time 2 | N4: =IF($M4="","",COUNTIF($M$2:$M4,$M4)) -> 2 | O4: =IF($M4="","",$M4&"|"&$N4) -> Time 2|2 | P4: =IF($E4="Midlane",1,0) -> 1 | Q4: =IF($P4=1,COUNTIF($P$2:$P4,1),"") -> 1
A5: THALISSON VIEIRA | B5: THALAO # FIRST | C5: Bronze | D5: {=INDEX('Valores por Elo'!$C$6:$C$15,MATCH($C5,'Valores por Elo'!$B$6:$B$15,0))} -> 2 | E5: Suport | F5: Suport | G5: =IF(ISNUMBER(SEARCH("Toplane",$F5)),1,0) -> 0 | H5: =IF(ISNUMBER(SEARCH("Jungler",$F5)),1,0) -> 0 | I5: =IF(ISNUMBER(SEARCH("Midlane",$F5)),1,0) -> 0 | J5: =IF(ISNUMBER(SEARCH("Adcarry",$F5)),1,0) -> 0 | K5: =IF(ISNUMBER(SEARCH("Suport",$F5)),1,0) -> 1 | L5: Não | M5: Time 2 | N5: =IF($M5="","",COUNTIF($M$2:$M5,$M5)) -> 3 | O5: =IF($M5="","",$M5&"|"&$N5) -> Time 2|3 | P5: =IF($E5="Midlane",1,0) -> 0 | Q5: =IF($P5=1,COUNTIF($P$2:$P5,1),"")
A6: Lucas Oliveira | B6: яαzεгαł ッ #yse | C6: Diamante | D6: {=INDEX('Valores por Elo'!$C$6:$C$15,MATCH($C6,'Valores por Elo'!$B$6:$B$15,0))} -> 8 | E6: Midlane | F6: Midlane | G6: =IF(ISNUMBER(SEARCH("Toplane",$F6)),1,0) -> 0 | H6: =IF(ISNUMBER(SEARCH("Jungler",$F6)),1,0) -> 0 | I6: =IF(ISNUMBER(SEARCH("Midlane",$F6)),1,0) -> 1 | J6: =IF(ISNUMBER(SEARCH("Adcarry",$F6)),1,0) -> 0 | K6: =IF(ISNUMBER(SEARCH("Suport",$F6)),1,0) -> 0 | L6: Não | M6: Time 5 | N6: =IF($M6="","",COUNTIF($M$2:$M6,$M6)) -> 1 | O6: =IF($M6="","",$M6&"|"&$N6) -> Time 5|1 | P6: =IF($E6="Midlane",1,0) -> 1 | Q6: =IF($P6=1,COUNTIF($P$2:$P6,1),"") -> 2
A7: Junior | B7: Sabor Energético #1777 | C7: Prata | D7: {=INDEX('Valores por Elo'!$C$6:$C$15,MATCH($C7,'Valores por Elo'!$B$6:$B$15,0))} -> 3 | E7: Midlane | F7: Midlane | G7: =IF(ISNUMBER(SEARCH("Toplane",$F7)),1,0) -> 0 | H7: =IF(ISNUMBER(SEARCH("Jungler",$F7)),1,0) -> 0 | I7: =IF(ISNUMBER(SEARCH("Midlane",$F7)),1,0) -> 1 | J7: =IF(ISNUMBER(SEARCH("Adcarry",$F7)),1,0) -> 0 | K7: =IF(ISNUMBER(SEARCH("Suport",$F7)),1,0) -> 0 | L7: Sim | M7: Time 4 | N7: =IF($M7="","",COUNTIF($M$2:$M7,$M7)) -> 1 | O7: =IF($M7="","",$M7&"|"&$N7) -> Time 4|1 | P7: =IF($E7="Midlane",1,0) -> 1 | Q7: =IF($P7=1,COUNTIF($P$2:$P7,1),"") -> 3
A8: Wafiter | B8: Top Lane 666 #BR1 | C8: Platina | D8: {=INDEX('Valores por Elo'!$C$6:$C$15,MATCH($C8,'Valores por Elo'!$B$6:$B$15,0))} -> 5 | E8: Toplane | F8: Toplane | G8: =IF(ISNUMBER(SEARCH("Toplane",$F8)),1,0) -> 1 | H8: =IF(ISNUMBER(SEARCH("Jungler",$F8)),1,0) -> 0 | I8: =IF(ISNUMBER(SEARCH("Midlane",$F8)),1,0) -> 0 | J8: =IF(ISNUMBER(SEARCH("Adcarry",$F8)),1,0) -> 0 | K8: =IF(ISNUMBER(SEARCH("Suport",$F8)),1,0) -> 0 | L8: Não | M8: Time 4 | N8: =IF($M8="","",COUNTIF($M$2:$M8,$M8)) -> 2 | O8: =IF($M8="","",$M8&"|"&$N8) -> Time 4|2 | P8: =IF($E8="Midlane",1,0) -> 0 | Q8: =IF($P8=1,COUNTIF($P$2:$P8,1),"")
A9: Silverio Junior | B9: Malasartes #7804 | C9: Bronze | D9: {=INDEX('Valores por Elo'!$C$6:$C$15,MATCH($C9,'Valores por Elo'!$B$6:$B$15,0))} -> 2 | E9: Jungler | F9: Jungler | G9: =IF(ISNUMBER(SEARCH("Toplane",$F9)),1,0) -> 0 | H9: =IF(ISNUMBER(SEARCH("Jungler",$F9)),1,0) -> 1 | I9: =IF(ISNUMBER(SEARCH("Midlane",$F9)),1,0) -> 0 | J9: =IF(ISNUMBER(SEARCH("Adcarry",$F9)),1,0) -> 0 | K9: =IF(ISNUMBER(SEARCH("Suport",$F9)),1,0) -> 0 | L9: Não | M9: Time 4 | N9: =IF($M9="","",COUNTIF($M$2:$M9,$M9)) -> 3 | O9: =IF($M9="","",$M9&"|"&$N9) -> Time 4|3 | P9: =IF($E9="Midlane",1,0) -> 0 | Q9: =IF($P9=1,COUNTIF($P$2:$P9,1),"")
A10: Jeferson/ Heimer | B10: N4firida agiota #7937 | C10: Ouro | D10: {=INDEX('Valores por Elo'!$C$6:$C$15,MATCH($C10,'Valores por Elo'!$B$6:$B$15,0))} -> 4 | E10: Midlane | F10: Midlane | G10: =IF(ISNUMBER(SEARCH("Toplane",$F10)),1,0) -> 0 | H10: =IF(ISNUMBER(SEARCH("Jungler",$F10)),1,0) -> 0 | I10: =IF(ISNUMBER(SEARCH("Midlane",$F10)),1,0) -> 1 | J10: =IF(ISNUMBER(SEARCH("Adcarry",$F10)),1,0) -> 0 | K10: =IF(ISNUMBER(SEARCH("Suport",$F10)),1,0) -> 0 | L10: Não | M10: Time 3 | N10: =IF($M10="","",COUNTIF($M$2:$M10,$M10)) -> 2 | O10: =IF($M10="","",$M10&"|"&$N10) -> Time 3|2 | P10: =IF($E10="Midlane",1,0) -> 1 | Q10: =IF($P10=1,COUNTIF($P$2:$P10,1),"") -> 4
A11: Alefh Nakayama | B11: nak4y#JPN | C11: Mestre | D11: {=INDEX('Valores por Elo'!$C$6:$C$15,MATCH($C11,'Valores por Elo'!$B$6:$B$15,0))} -> 10 | E11: Jungler | F11: Jungler | G11: =IF(ISNUMBER(SEARCH("Toplane",$F11)),1,0) -> 0 | H11: =IF(ISNUMBER(SEARCH("Jungler",$F11)),1,0) -> 1 | I11: =IF(ISNUMBER(SEARCH("Midlane",$F11)),1,0) -> 0 | J11: =IF(ISNUMBER(SEARCH("Adcarry",$F11)),1,0) -> 0 | K11: =IF(ISNUMBER(SEARCH("Suport",$F11)),1,0) -> 0 | L11: Não | M11: Time 1 | N11: =IF($M11="","",COUNTIF($M$2:$M11,$M11)) -> 1 | O11: =IF($M11="","",$M11&"|"&$N11) -> Time 1|1 | P11: =IF($E11="Midlane",1,0) -> 0 | Q11: =IF($P11=1,COUNTIF($P$2:$P11,1),"")
A12: Carlos Daniel | B12: SOU ADC NÃO DEUS#BR1 | C12: Esmeralda | D12: {=INDEX('Valores por Elo'!$C$6:$C$15,MATCH($C12,'Valores por Elo'!$B$6:$B$15,0))} -> 6 | E12: Adcarry | F12: Adcarry | G12: =IF(ISNUMBER(SEARCH("Toplane",$F12)),1,0) -> 0 | H12: =IF(ISNUMBER(SEARCH("Jungler",$F12)),1,0) -> 0 | I12: =IF(ISNUMBER(SEARCH("Midlane",$F12)),1,0) -> 0 | J12: =IF(ISNUMBER(SEARCH("Adcarry",$F12)),1,0) -> 1 | K12: =IF(ISNUMBER(SEARCH("Suport",$F12)),1,0) -> 0 | L12: Não | M12: Time 4 | N12: =IF($M12="","",COUNTIF($M$2:$M12,$M12)) -> 4 | O12: =IF($M12="","",$M12&"|"&$N12) -> Time 4|4 | P12: =IF($E12="Midlane",1,0) -> 0 | Q12: =IF($P12=1,COUNTIF($P$2:$P12,1),"")
A13: Relbert Mateus | B13: MIDAS#Ayla | C13: Esmeralda | D13: {=INDEX('Valores por Elo'!$C$6:$C$15,MATCH($C13,'Valores por Elo'!$B$6:$B$15,0))} -> 6 | E13: Suport | F13: Suport | G13: =IF(ISNUMBER(SEARCH("Toplane",$F13)),1,0) -> 0 | H13: =IF(ISNUMBER(SEARCH("Jungler",$F13)),1,0) -> 0 | I13: =IF(ISNUMBER(SEARCH("Midlane",$F13)),1,0) -> 0 | J13: =IF(ISNUMBER(SEARCH("Adcarry",$F13)),1,0) -> 0 | K13: =IF(ISNUMBER(SEARCH("Suport",$F13)),1,0) -> 1 | L13: Não | M13: Time 5 | N13: =IF($M13="","",COUNTIF($M$2:$M13,$M13)) -> 2 | O13: =IF($M13="","",$M13&"|"&$N13) -> Time 5|2 | P13: =IF($E13="Midlane",1,0) -> 0 | Q13: =IF($P13=1,COUNTIF($P$2:$P13,1),"")
... A31: Nicollas Castro | B31: ctz #444 | C31: Diamante | D31: {=INDEX('Valores por Elo'!$C$6:$C$15,MATCH($C31,'Valores por Elo'!$B$6:$B$15,0))} -> 8 | E31: Adcarry | F31: Adcarry | G31: =IF(ISNUMBER(SEARCH("Toplane",$F31)),1,0) -> 0 | H31: =IF(ISNUMBER(SEARCH("Jungler",$F31)),1,0) -> 0 | I31: =IF(ISNUMBER(SEARCH("Midlane",$F31)),1,0) -> 0 | J31: =IF(ISNUMBER(SEARCH("Adcarry",$F31)),1,0) -> 1 | K31: =IF(ISNUMBER(SEARCH("Suport",$F31)),1,0) -> 0 | L31: Não | M31: Time 2 | N31: =IF($M31="","",COUNTIF($M$2:$M31,$M31)) -> 5 | O31: =IF($M31="","",$M31&"|"&$N31) -> Time 2|5 | P31: =IF($E31="Midlane",1,0) -> 0 | Q31: =IF($P31=1,COUNTIF($P$2:$P31,1),"")

Sheet Valores por Elo
B2: Tabela de Pontos por Elo
B3: Edite a coluna 'Valor (pontos)' para recalibrar — o restante da planilha recalcula sozinho.
B5: Elo | C5: Valor (pontos) | D5: Jogadores nesta edição
B6: Ferro | C6: 1 | D6: =COUNTIF('Base Jogadores'!$C$2:$C$31,$B6) -> 0
B7: Bronze | C7: 2 | D7: =COUNTIF('Base Jogadores'!$C$2:$C$31,$B7) -> 3
B8: Prata | C8: 3 | D8: =COUNTIF('Base Jogadores'!$C$2:$C$31,$B8) -> 2
B9: Ouro | C9: 4 | D9: =COUNTIF('Base Jogadores'!$C$2:$C$31,$B9) -> 5
B10: Platina | C10: 5 | D10: =COUNTIF('Base Jogadores'!$C$2:$C$31,$B10) -> 8
B11: Esmeralda | C11: 6 | D11: =COUNTIF('Base Jogadores'!$C$2:$C$31,$B11) -> 7
B12: Diamante | C12: 8 | D12: =COUNTIF('Base Jogadores'!$C$2:$C$31,$B12) -> 4
B13: Mestre | C13: 10 | D13: =COUNTIF('Base Jogadores'!$C$2:$C$31,$B13) -> 1
B14: Grão-Mestre | C14: 12 | D14: =COUNTIF('Base Jogadores'!$C$2:$C$31,$B14) -> 0
B15: Desafiante | C15: 15 | D15: =COUNTIF('Base Jogadores'!$C$2:$C$31,$B15) -> 0
B18: Resumo do pool de jogadores
B19: Total de jogadores inscritos | C19: =COUNTA('Base Jogadores'!$A$2:$A$31) -> 30
B20: Total de pontos do pool | C20: =SUM('Base Jogadores'!$D$2:$D$31) -> 156
B21: Times sugeridos (5 jogadores cada) | C21: =ROUND(C20/5/5,0) -> 6
B22: Orçamento médio por time (pool ÷ times) | C22: =ROUND(C20/C21,1) -> 26
B23: Orçamento recomendado por capitão (+15% de folga) | C23: =ROUNDUP(C22*1.15,0) -> 30
B25: Metodologia: os pontos crescem de forma não-linear entre elos (Ferro=1 ... Desafiante=15), refletindo que o salto de habilidade entre elos altos é maior que entre elos baixos. O orçamento recomendado para cada capitão é a média de pontos por time com uma folga de 15%, o suficiente para que ele consiga competir por jogadores de elo mais alto sem conseguir empilhar vários de uma vez — isso é o que força o equilíbrio entre os times.

Sheet Respostas (original)
A1: Carimbo de data/hora | B1: Nome e sobrenome para localizar no grupo do WhatsApp | C1: Nickname com # para ser localizado no dia da partida | D1: Qual o seu elo atualmente na SOLO/DUO? | E1: Qual a sua rota primária? | F1: Está ciente que precisará pagar antes do início do torneio? Lembrando que vamos definir ainda o valor. | G1: Você é mono champion?
A2: 2026-07-13 10:15:44 | B2: Luiz Felipe | C2: mxxDragonxxm | D2: Diamante | E2: Jungler | F2: Sim | G2: Não
A3: 2026-07-13 10:16:01 | B3: Hygor rodrigo | C3: Hikolin#2112 | D3: Esmeralda | E3: Adcarry | F3: Sim | G3: Não
A4: 2026-07-13 10:17:33 | B4: Felipe / Satoshi | C4: Satoshi #VDD | D4: Platina | E4: Midlane | F4: Sim | G4: Não
A5: 2026-07-13 10:19:50 | B5: THALISSON VIEIRA | C5: THALAO # FIRST | D5: Bronze | E5: Suport | F5: Sim | G5: Não
A6: 2026-07-13 10:27:34 | B6: Lucas Oliveira | C6: яαzεгαł ッ #yse | D6: Diamante | E6: Midlane | F6: Sim | G6: Não
A7: 2026-07-13 10:37:19 | B7: Junior | C7: Sabor Energético #1777 | D7: Prata | E7: Midlane | F7: Sim | G7: Sim
A8: 2026-07-13 10:40:16 | B8: Wafiter | C8: Top Lane 666 #BR1 | D8: Platina | E8: Toplane | F8: Sim | G8: Não
A9: 2026-07-13 10:45:06 | B9: Silverio Junior | C9: Malasartes | D9: Bronze | E9: Jungler | F9: Sim | G9: Não
A10: 2026-07-13 11:43:02 | B10: Jeferson/ Heimer | C10: N4firida agiota #7937 | D10: Ouro | E10: Midlane | F10: Sim | G10: Não
A11: 2026-07-13 11:45:33 | B11: Alefh Nakayama | C11: nak4y#JPN | D11: Mestre | E11: Jungler | F11: Sim | G11: Não
A12: 2026-07-13 11:48:47 | B12: Carlos Daniel | C12: SOU ADC NÃO DEUS#BR1 | D12: Esmeralda | E12: Adcarry | F12: Sim | G12: Não
... A31: 2026-07-15 15:39:03 | B31: Nicollas Castro | C31: ctz #444 | D31: Diamante | E31: Adcarry | F31: Sim | G31: Não
